Workbook
Name Categories: [1]Header!$A$36:$A$39
Name Categories: [1]Header!$A$36:$A$39
Name Categories: [1]Header!$A$36:$A$39
Name Categories: [1]Header!$A$36:$A$39
Name Categories: Header!$A$36:$A$39
Name LIST: Header!$A$36:$A$38

Sheet Header
A3: Checkliste
A4: Projekt: | B4: PEGASUS
A7: Zielgesellschaft | B7: Zielgesellschafts GmbH
A9: Reporting Periode
A11: Historische Informationen | B11: GJ19 - GJ20 (Actual/Audited) aktuelles GJ21
A12: Business Plan | B12: GJ21- GJ25 (Plan/Budget)
A16: Updated:
A17: 44552
A36: Offen
A37: Teilweise offen
A38: Erhalten
A39: k.A.

Sheet Geschäftsübersicht
D1: =+Header!A3 -> Checkliste | H1: Update | I1: =+Header!A17 -> 44552
B2: Projekt | D2: =+Header!B4 -> PEGASUS
B3: Sektor | D3: Business Überblick
B5: Linie | C5: Priorität | D5: Info / Dokument | E5: Gruppen | F5: Einheits | G5: Verantwortlich | H5: Kommentar | I5: Status | K5: Einheit 1 | L5: Einheit 2
E6: Ebene | F6: Ebene
B8: =1+(ROW(B8)-7)/100 -> 1.01 | D8: Allgemeine Informationen über angebotene Produkte, bediente Kunden und Kundensegmente und relevante Märkte; inkl. anderer für die Unternehmensstrategie relevanter Präsentationen | I8: offen | K8: offen | L8: offen
B9: =1+(ROW(B9)-7)/100 -> 1.02 | D9: Statutarische Jahresabschlüsse seit 2019 | I9: offen | K9: offen | L9: offen
B10: =1+(ROW(B10)-7)/100 -> 1.03 | D10: Derzeitige rechtliche Konzernstruktur mit Angabe der rechtlichen Einheiten | I10: offen | K10: offen | L10: offen
B11: =1+(ROW(B11)-7)/100 -> 1.04 | D11: Aktuelle Managementstruktur mit Aufteilung der Zuständigkeiten, Namen der wichtigsten Führungskräfte und Anzahl der Mitarbeiter pro Abteilung | I11: offen | K11: offen | L11: offen
B12: =1+(ROW(B12)-7)/100 -> 1.05 | D12: Kurze Zusammenfassung der Historie mit Hervorhebung wichtiger Ereignisse, einschließlich größerer Umstrukturierungen, Übernahmen und Veräußerungen, Käufe oder Verkäufe von Wettbewerbern/Geschäftsbereichen einschließlich der finanziellen Auswirkungen | I12: offen | K12: offen | L12: offen
B13: =1+(ROW(B13)-7)/100 -> 1.06 | D13: Liste der wichtigsten Leistungsindikatoren (KPI) und kritischen Erfolgsfaktoren, die von der Geschäftsleitung ermittelt und verwendet werden | I13: offen | K13: offen | L13: offen
B14: =1+(ROW(B14)-7)/100 -> 1.07 | D14: Monatliche Verwaltungskonten seit Jan. 2019 | I14: offen | K14: offen | L14: offen
B15: =1+(ROW(B15)-7)/100 -> 1.08 | D15: Weitere seit 2019 veröffentlichte Lageberichte | I15: offen | K15: offen | L15: offen
B16: =1+(ROW(B16)-7)/100 -> 1.09 | D16: Dokumentation des Risikomanagements (Verfahren und ermittelte Risiken) | I16: offen | K16: offen | L16: offen
B17: =1+(ROW(B17)-7)/100 -> 1.1 | D17: Protokolle von Vorstandssitzungen (Protokolle von Beiratssitzungen, Protokolle von Vorstandssitzungen) | I17: offen | K17: offen | L17: offen
B18: =1+(ROW(B18)-7)/100 -> 1.11 | D18: Handbuch zur Rechnungslegung der Gruppe, Beschreibung der wichtigsten Rechnungslegungskontrollen und des Kontrollumfelds der Gruppe, Änderungen der Rechnungslegungsmethoden | I18: offen | K18: offen | L18: offen
B19: =1+(ROW(B19)-7)/100 -> 1.12 | D19: Kopie der Treasury-Politik und Beschreibung der Organisation und der Verfahren der Finanzabteilung, einschließlich der Kontrolle und Überwachung des Wechselkursrisikos und des Devisenmanagements (Hedging-Politik) | I19: offen | K19: offen | L19: offen
... B26: =1+(ROW(B26)-7)/100 -> 1.19 | D26: Liste der seit der Ausgliederung erhaltenen öffentlichen Zuschüsse, damit verbundene Bedingungen und buchhalterische Behandlung | I26: offen | K26: offen | L26: offen

Sheet Markt und Kunden
D1: =+Header!A3 -> Checkliste | H1: Update | I1: =+Header!A17 -> 44552
B2: Projekt: | D2: =+Header!B4 -> PEGASUS
B3: Sektion: | D3: Markt, Kunden, Wettbewerbsumfeld
B5: Linie | C5: Priorität | D5: Info / Dokument | E5: Gruppen | F5: Einheits | G5: Verantwortlich | H5: Kommentar | I5: Status | K5: Einheit 1 | L5: Einheit 2
E6: Ebene | F6: Ebene
B8: =1+(ROW(B8)-7)/100 -> 1.01 | D8: Unternehmensschätzungen zur relevanten Marktgröße und zum (historischen, zukünftigen) Wachstum nach: Produkten/Segmenten, Kunden, regionalen Märkten | I8: offen | K8: offen | L8: offen
B9: =1+(ROW(B9)-7)/100 -> 1.02 | D9: Einschätzung des Managements zu den wichtigsten aktuellen und zukünftigen Marktfaktoren und Entwicklungen | I9: offen | K9: offen | L9: offen
B10: =1+(ROW(B10)-7)/100 -> 1.03 | D10: Informationen über historische und zukünftige Marktpreisentwicklungen für Produkte/Segmente | I10: offen | K10: offen | L10: offen
B11: =1+(ROW(B11)-7)/100 -> 1.04 | D11: Alle relevanten Marktberichte über Größe, Wachstum oder Trends für die betreffenden Produkte/Segmente | I11: offen | K11: offen | L11: offen
B12: =1+(ROW(B12)-7)/100 -> 1.05 | D12: Sicht des Managements auf den Kaufprozess der Kunden und die wichtigsten Entscheidungsträger | I12: offen | K12: offen | L12: offen
B13: =1+(ROW(B13)-7)/100 -> 1.06 | D13: Management-Sicht auf das Preismodell innerhalb der Kundengruppen (bestehende und geplante) inkl. Contracting | I13: offen | K13: offen | L13: offen
B14: =1+(ROW(B14)-7)/100 -> 1.07 | D14: Ansicht des Managements zu den wichtigsten Kauf-/Auswahlkriterien | I14: offen | K14: offen | L14: offen
B15: =1+(ROW(B15)-7)/100 -> 1.08 | D15: Diskussion über Kundentreue und Kundenwechselverhalten | I15: offen | K15: offen | L15: offen
B16: =1+(ROW(B16)-7)/100 -> 1.09 | D16: Informationen zur historischen Kundenbindung | I16: offen | K16: offen | L16: offen
B17: =1+(ROW(B17)-7)/100 -> 1.1 | D17: Bewertung der strategischen Differenzierung des Zielunternehmens sowie seiner Stärken und Schwächen aus Sicht der Kunden | I17: offen | K17: offen | L17: offen
B18: =1+(ROW(B18)-7)/100 -> 1.11 | D18: Alle relevanten Informationen oder Marktforschungen zur Kundenbindung oder zu Trends | I18: offen | K18: offen | L18: offen
B19: =1+(ROW(B19)-7)/100 -> 1.12 | D19: Diskussion über Preisanpassungsklauseln (falls relevant) | I19: offen | K19: offen | L19: offen
... B22: =1+(ROW(B22)-7)/100 -> 1.15 | D22: Alle relevanten Informationen oder Analysen über Konkurrenten oder die Wettbewerbsposition (einschließlich Marktanteile) | I22: offen | K22: offen | L22: offen

Sheet Historische Zahlen
D1: =+Header!A3 -> Checkliste | H1: =+[2]Header!$A$16 -> Updated: | I1: =[2]Header!A17 -> 40808
B2: Projekt: Circle | D2: =+Header!B4 -> PEGASUS
B3: Sektion: | D3: Historische Handelsresultate
B5: Linie | C5: Priorität | D5: Info / Dokument | E5: Gruppen | F5: Einheits | G5: Verantwortlich | H5: Kommentar | I5: Status | K5: Einheit 1 | L5: Einheit 2
E6: Ebene | F6: Ebene
B8: =2+(ROW(B8)-7)/100 -> 2.01 | D8: Darstellung der jährlichen Entwicklung des historischen EBIT nach Wechselkurs-, Preis-, Mengen-, Umsatzmix-, Materialkosten- und Gemeinkostenentwicklung (Brückendaten) | I8: offen | K8: offen | L8: offen
B9: =2+(ROW(B9)-7)/100 -> 2.02 | D9: Dokumentation der Jahresendkonsolidierung | I9: offen | K9: offen | L9: offen
B10: =2+(ROW(B10)-7)/100 -> 2.03 | D10: Umsatz nach Produkten/Segmenten, Kunden, regionalen Märkten (monatlich und jährlich) | I10: offen | K10: offen | L10: offen
B11: =2+(ROW(B11)-7)/100 -> 2.04 | D11: Preise und Mengen nach Produkten/Segmenten, Kunden, regionalen Märkten (monatlich und jährlich) | I11: offen | K11: offen | L11: offen
B12: =2+(ROW(B12)-7)/100 -> 2.05 | D12: Rentabilität / Bruttomarge / EBITDA nach Produkten/Segmenten, Kunden, regionalen Märkten (monatlich und jährlich) | I12: offen | K12: offen | L12: offen
B13: =2+(ROW(B13)-7)/100 -> 2.06 | D13: Informationen über die wichtigsten Faktoren für Umsatz und Rentabilität nach Produkten/Segmenten, Kunden und regionalen Märkten (monatlich und jährlich) | I13: offen | K13: offen | L13: offen
B14: =2+(ROW(B14)-7)/100 -> 2.07 | D14: Informationen über die wichtigsten Änderungen im Produktmix und geplante Änderungen innerhalb des Planungszeitraums | I14: offen | K14: offen | L14: offen
B15: =2+(ROW(B15)-7)/100 -> 2.08 | D15: Analyse der fixen und variablen Kosten (für alle großen Einheiten) | I15: offen | K15: offen | L15: offen
B16: =2+(ROW(B16)-7)/100 -> 2.09 | D16: Aufschlüsselung der VVG-Kosten (Vertrieb und Marketing, F&E, allgemeine Verwaltung und sonstige Einnahmen und Ausgaben) | I16: offen | K16: offen | L16: offen
B17: =2+(ROW(B17)-7)/100 -> 2.1 | D17: Zusammenfassung der wesentlichen konzerninternen Kostenzuweisungen und Beschreibung der Zuweisungsmethodik | I17: offen | K17: offen | L17: offen
B18: =2+(ROW(B18)-7)/100 -> 2.11 | D18: Einzelheiten (Beschreibung und Betrag) aller außergewöhnlichen oder einmaligen oder nichtoperativen Posten (einschließlich Änderungen der Rechnungslegungsgrundsätze, Auflösung von Rückstellungen usw.) | I18: offen | K18: offen | L18: offen
B19: =2+(ROW(B19)-7)/100 -> 2.12 | D19: Detaillierte Informationen über alle anderen Aspekte, die die Vergleichbarkeit der Ergebnisse beeinträchtigen | I19: offen | K19: offen | L19: offen
... B26: =2+(ROW(B26)-7)/100 -> 2.19 | D26: Vergleich der ursprünglichen historischen GuV-Budgets mit den tatsächlichen Ergebnissen und Erläuterung wesentlicher Abweichungen (einschließlich Investitionsbudgets) | I26: offen | K26: offen | L26: offen

Sheet Bilanz
D1: =+Header!A3 -> Checkliste | H1: =+[2]Header!$A$16 -> Updated: | I1: =[2]Header!A17 -> 40808
B2: Projekt: | D2: =+Header!B4 -> PEGASUS
B3: Sektion | D3: Historische Jahresabschlüsse
B5: Line | C5: Priorität | D5: Info / Dokument | E5: Gruppen | F5: Einheits | G5: Verantwortlich | H5: Kommentar | I5: Status | K5: Einheit 1 | L5: Einheit 2
E6: Ebene | F6: Ebene
B8: =3+(ROW(B8)-7)/100 -> 3.01 | D8: Liste von Vermögenswerten, deren Marktwert erheblich vom Buchwert abweicht, mit Angabe eines angemessenen Marktwerts (insbesondere Grundstücke und Gebäude) | I8: offen | K8: offen | L8: offen
B9: =3+(ROW(B9)-7)/100 -> 3.02 | D9: Liste von Vermögenswerten, die in keinem Zusammenhang mit dem Unternehmen stehen oder für das Unternehmen nicht erforderlich sind | I9: offen | K9: offen | L9: offen
B10: =3+(ROW(B10)-7)/100 -> 3.03 | D10: Für die wichtigsten Kategorien von Sachanlagen sind das durchschnittliche Alter der Anlagen, die Nutzungsdauer, die Abschreibungssätze und -grundsätze sowie Einzelheiten zu etwaigen Wertminderungen/Abschreibungen anzugeben. | I10: offen | K10: offen | L10: offen
B11: =3+(ROW(B11)-7)/100 -> 3.04 | D11: Anlagenspiegel, der die jährliche Entwicklung der Kosten und der Abschreibung von Anlagegütern zeigt | I11: offen | K11: offen | L11: offen
B12: =3+(ROW(B12)-7)/100 -> 3.05 | D12: Finanzierungs- und Operating-Leasingverhältnisse (Leasing in); detaillierte Angaben zu allen wesentlichen Leasingverhältnissen, einschließlich Beschreibung, Bedingungen, Kaufoptionen, jährliche Zahlungen, Zinsanteil | I12: offen | K12: offen | L12: offen
B13: =3+(ROW(B13)-7)/100 -> 3.06 | D13: Analyse der Wertminderung von Goodwill und anderen immateriellen Vermögenswerten | I13: offen | K13: offen | L13: offen
B14: =3+(ROW(B14)-7)/100 -> 3.07 | D14: Einzelheiten der Vorratsreserven nach Kategorie; Berechnungsmethode | I14: offen | K14: offen | L14: offen
B15: =3+(ROW(B15)-7)/100 -> 3.08 | D15: Berechnung/Aufschlüsselung und Entwicklung allgemeiner und spezifischer Wertberichtigungen für zweifelhafte Forderungen, Forderungsausfallhistorie und Analyse von Rücksendungen | I15: offen | K15: offen | L15: offen
B16: =3+(ROW(B16)-7)/100 -> 3.09 | D16: Fälligkeitsanalyse der Forderungen für die geprüften Jahresenddaten; Erläuterung etwaiger signifikanter Bewegungen in den Fälligkeitskategorien; größere überfällige Forderungen im GJ20 | I16: offen | K16: offen | L16: offen
B17: =3+(ROW(B17)-7)/100 -> 3.1 | D17: Detaillierte Aufgliederung der sonstigen Aktiva und Passiva, einschließlich der laufenden Steuerforderungen und -verbindlichkeiten, insbesondere die Trennung von Handels- und Finanzposten | I17: offen | K17: offen | L17: offen
B18: =3+(ROW(B18)-7)/100 -> 3.11 | D18: Berechnung der Pensionsrückstellungen | I18: offen | K18: offen | L18: offen
B19: =3+(ROW(B19)-7)/100 -> 3.12 | D19: Auflistung aller wesentlichen Forderungen und Gegenforderungen, einschließlich Einzelheiten zur Behandlung in der Rechnungslegung | I19: offen | K19: offen | L19: offen
... B23: =3+(ROW(B23)-7)/100 -> 3.16 | D23: Angaben zu Eventualverbindlichkeiten, Kaufverpflichtungen und sonstigen außerbilanziellen Verpflichtungen | I23: offen | K23: offen | L23: offen

Sheet Cash Flows
D1: =+Header!A3 -> Checkliste | H1: Update | I1: =+Header!A17 -> 44552
B2: Projekt: | D2: =+Header!B4 -> PEGASUS
B3: Section: | D3: Historische Cashflows
B5: Linie | C5: Priorität | D5: Info / Dokument | E5: Gruppen | F5: Einheits | G5: Verantwortlich | H5: Kommentar | I5: Status | K5: Einheit 1 | L5: Einheit 2
E6: Ebene | F6: Ebene
B8: =4+(ROW(B8)-7)/100 -> 4.01 | D8: Jährliche Cashflow-Berechnung / Cashflow-Rechnung | I8: offen | K8: offen | L8: offen
B9: =4+(ROW(B9)-7)/100 -> 4.02 | D9: Bereitstellung von untermonatlichen Bargeldbewegungen (Analyse des Spitzenbedarfs an Bargeld) | I9: offen | K9: offen | L9: offen
B10: =4+(ROW(B10)-7)/100 -> 4.03 | D10: Einzelheiten zu den Auswirkungen aller wesentlichen einmaligen / nichtoperativen Posten auf die Liquidität | I10: offen | K10: offen | L10: offen
B11: =4+(ROW(B11)-7)/100 -> 4.04 | D11: Investitionen nach Rechtsperson und Kategorie (Ersatz, Wachstum, Kostensenkung, Sicherheit/Umweltschutz, F&E), einschließlich Erläuterung der wichtigsten Posten/Projekte | I11: offen | K11: offen | L11: offen

Sheet Business Plan
D1: =+Header!A3 -> Checkliste | H1: =+[2]Header!$A$16 -> Updated: | I1: =[2]Header!A17 -> 40808
B2: Projekt | D2: =+Header!B4 -> PEGASUS
B3: Sektion: | D3: Vorhersage und Budget
B5: Linie | C5: Priorität | D5: Info / Dokument | E5: Gruppen | F5: Einheits | G5: Verantwortlich | H5: Kommentar | I5: Status | K5: Einheit 1 | L5: Einheit 2
E6: Ebene | F6: Ebene
B8: =5+(ROW(B8)-7)/100 -> 5.01 | D8: Darstellung der aktuellen Geschäfts- und Betriebsstrategie der Gruppe | I8: offen | K8: offen | L8: offen
B9: =5+(ROW(B9)-7)/100 -> 5.02 | D9: Detaillierte Beschreibung des Planungsprozesses der Gruppe | I9: offen | K9: offen | L9: offen
B10: =5+(ROW(B10)-7)/100 -> 5.03 | D10: Detaillierte Beschreibung der Planungsannahmen (inkl. Preis-, Mengen- und Hauptkostenpositionen) | I10: offen | K10: offen | L10: offen
B11: =5+(ROW(B11)-7)/100 -> 5.04 | D11: Ansicht des Managements zu alternativen Annahmen oder Szenarioberechnungen | I11: offen | K11: offen | L11: offen
B12: =5+(ROW(B12)-7)/100 -> 5.05 | D12: Einzelheiten zum Geschäftsplan (Gewinn und Verlust, Cashflow und Bilanzen), einschließlich Planungspakete, vergleichbar mit historischen Informationen | I12: offen | K12: offen | L12: offen
B13: =5+(ROW(B13)-7)/100 -> 5.06 | D13: Kommentieren Sie die wichtigsten Trends in den Projektionen und erläutern Sie die Pläne zur Finanzierung des geplanten Wachstums. | I13: offen | K13: offen | L13: offen
B14: =5+(ROW(B14)-7)/100 -> 5.07 | D14: Detaillierter Absatzplan (Menge, Preis und Wert) nach Produkt/Segment, Kunde, regionalen Märkten | I14: offen | K14: offen | L14: offen
B15: =5+(ROW(B15)-7)/100 -> 5.08 | D15: Analyse der geplanten Bruttomarge nach Rechtseinheit / Produktkategorie und auf Konzernebene | I15: offen | K15: offen | L15: offen
B16: =5+(ROW(B16)-7)/100 -> 5.09 | D16: Detaillierte Analyse des geplanten Personalbestands (FTE) und der Kosten pro Kopf für direkte und indirekte Mitarbeiter | I16: offen | K16: offen | L16: offen
B17: =5+(ROW(B17)-7)/100 -> 5.1 | D17: Dokumentation des geplanten konzerninternen Handels und Konsolidierung der prognostizierten Finanzinformationen | I17: offen | K17: offen | L17: offen
B18: =5+(ROW(B18)-7)/100 -> 5.11 | D18: Beschreibung wichtiger geplanter Produkteinführungen und geplanter Investitionsprojekte, einschließlich aktivierter Kosten, zugehöriger Ausgaben und Kategorie (Ersatz, Wachstum, Kostensenkung, F&E) | I18: offen | K18: offen | L18: offen

Sheet Tax
D1: =+Header!A3 -> Checkliste | H1: Update | I1: =+Header!A17 -> 44552
B2: Projekt | D2: =+Header!B4 -> PEGASUS
B3: Sektion | D3: Tax (Steuern)
B5: Linie | C5: Priorität | D5: Info / Dokument | E5: Gruppen | F5: Einheits | G5: Verantwortlich | H5: Kommentar | I5: Status | K5: Einheit 1 | L5: Einheit 2
E6: Ebene | F6: Ebene
D8: Allgemeiner Hintergrund
B9: =6+(ROW(B9)-8)/100 -> 6.01 | D9: Geprüfte Jahresabschlüsse für die Geschäftsjahre 2019 und 20. | I9: offen | K9: offen | L9: offen
B10: =6+(ROW(B10)-8)/100 -> 6.02 | D10: Geprüfte Jahresabschlüsse für die Geschäftsjahre 2018 und 19. | I10: offen | K10: offen | L10: offen
B11: =6+(ROW(B11)-8)/100 -> 6.03 | D11: Geprüfte Jahresabschlüsse für die Geschäftsjahre 2018 und 2019. | I11: offen | K11: offen | L11: offen
B12: =6+(ROW(B12)-8)/100 -> 6.04 | D12: Angaben zu wesentlichen Umstrukturierungen der Gruppe (z. B. Fusion, Umwandlung, Einbringung, Abspaltung, Änderung der Beherrschungsverhältnisse usw.), Akquisitionen oder Veräußerungen in den letzten drei Jahren, einschließlich etwaiger gruppeninterner Vermögensübertragungen in den letzten drei Jahren. | I12: offen | K12: offen | L12: offen
B13: =6+(ROW(B13)-8)/100 -> 6.05 | D13: Angaben darüber, wer bei der Zielgesellschaft für die Einhaltung der Steuervorschriften und die Steuerplanung zuständig ist, sowie Angaben zu den in Anspruch genommenen externen Beratern. | I13: offen | K13: offen | L13: offen
B14: =6+(ROW(B14)-8)/100 -> 6.06 | D14: Eine Zusammenfassung aller internen und externen Anleihen jedes Unternehmens, einschließlich der wichtigsten Bedingungen der Anleihen. | I14: offen | K14: offen | L14: offen
D15: Steuerprüfung / Steuerstatus
B16: =6+(ROW(B16)-9)/100 -> 6.07 | D16: Kopien der Steuerberechnungen, Steuererklärungen (einschließlich aller Anlagen zu den Erklärungen) und Steuerbescheide für die Jahre 2018, 2019 und 20, einschließlich aller geänderten Erklärungen und Bescheide. | I16: offen | K16: offen
B17: =6+(ROW(B17)-9)/100 -> 6.08 | D17: Alle wichtigen Mitteilungen an die Finanzbehörden in Bezug auf die Steuererklärungen der Zielunternehmen (z. B. verbindliche Bescheide usw.), einschließlich Einzelheiten zu anhängigen Rechtsbehelfen und Gerichtsverfahren. | I17: offen | K17: offen
B18: =6+(ROW(B18)-9)/100 -> 6.09 | D18: Beantragte/gewährte Fristverlängerungen für die Abgabe von Steuererklärungen. | I18: offen | K18: offen
B19: =6+(ROW(B19)-9)/100 -> 6.1 | D19: Kopien der an die Mitglieder der Zielgruppe gerichteten Steuervorauszahlungsbescheide. | I19: offen | K19: offen
B20: =6+(ROW(B20)-9)/100 -> 6.11 | D20: Bestätigung, dass die Steuerzahlungen pünktlich und ordnungsgemäß verbucht worden sind. | I20: offen | K20: offen
B21: =6+(ROW(B21)-9)/100 -> 6.12 | D21: Kopien von Quellensteuererklärungen und Bescheiden über zugerechnete Zinsen, Dividenden usw. seit der letzten Steuerprüfung. | I21: offen | K21: offen
B22: =6+(ROW(B22)-9)/100 -> 6.13 | D22: Bestätigung, dass die Quellensteuer (WHT) auf relevante Zahlungen (einschließlich Zinsen) korrekt verbucht wurde oder dass die Finanzbehörden entsprechende Befreiungen von der WHT gewährt haben (einschließlich Kopien der WHT-Befreiungsbescheinigung). | I22: offen | K22: offen
B23: =6+(ROW(B23)-9)/100 -> 6.14 | D23: Kopien der letzten Steuerprüfungsberichte und Ankündigung von Steuerprüfungen sowie Einzelheiten zu laufenden Steuerprüfungen (Liste der aktuellen Feststellungen). | I23: offen | K23: offen
B24: =6+(ROW(B24)-9)/100 -> 6.15 | D24: Einzelheiten zu etwaigen Berichtigungen späterer Steuererklärungen, die sich aus den Berichtigungen früherer Steuerprüfungen ergeben. | I24: offen | K24: offen
D25: Steuerliche Attribute
B26: =6+(ROW(B26)-10)/100 -> 6.16 | D26: Angaben zu den steuerlichen Verlustvorträgen der Zielgesellschaft zum Ende des GJ20 | I26: offen | K26: offen
D27: Jahresabschlüsse
B28: =6+(ROW(B28)-11)/100 -> 6.17 | D28: Übersicht/Split/Berechnung der Steuerforderungen, Steuerverbindlichkeiten und Steuerrückstellungen im Jahresabschluss der Zielgesellschaft für das Geschäftsjahr 2020. | I28: offen | K28: offen
B29: =6+(ROW(B29)-11)/100 -> 6.18 | D29: Eine Analyse der in den Jahresabschlüssen der Zielgesellschaft für die Geschäftsjahre 2019 und 2020 ausgewiesenen Steuerbelastung in der Gewinn- und Verlustrechnung, einschließlich einer Überleitung des effektiven Steuersatzes in der Bilanz zum gesetzlichen Steuersatz. | I29: offen | K29: offen
B30: =6+(ROW(B30)-11)/100 -> 6.19 | D30: Arbeitspapiere, die die Berechnung der aktiven und passiven latenten Steuern in den Bilanzen der GJ19 und GJ20 der Zielgesellschaft zeigen. | I30: offen | K30: offen
D31: Verrechnungspreise
B32: =6+(ROW(B32)-12)/100 -> 6.2 | D32: Einzelheiten über die Art der konzerninternen Transaktionen (z. B. konzerninterne Darlehen, konzerninterne Dienstleistungen, konzerninterne Warenverkäufe) und konzerninterne Kostenbelastungen, einschließlich Einzelheiten zu: | I32: offen | K32: offen
B33: =6+(ROW(B33)-12)/100 -> 6.21 | D33: a. wie der Verrechnungspreis berechnet wird (Bitte legen Sie die unterzeichneten Verträge vor)
B34: =6+(ROW(B34)-12)/100 -> 6.22 | D34: b. ungefährer jährlicher Wert der gruppeninternen Transaktionen
B35: =6+(ROW(B35)-12)/100 -> 6.23 | D35: Angaben zu jeglichem vom Unternehmen genutzten geistigen Eigentum (IP), zu den Eigentumsverhältnissen des IP und zu allen Zahlungen, die das Unternehmen für die Nutzung des IP geleistet hat. | I35: offen | K35: offen
B36: =6+(ROW(B36)-12)/100 -> 6.24 | D36: Bestätigung, dass die Dokumentationsanforderungen in Bezug auf die Verrechnungspreise erfüllt wurden. | I36: offen | K36: offen
B37: =6+(ROW(B37)-12)/100 -> 6.25 | D37: Angaben zu etwaigen Darlehen von verbundenen Parteien oder Darlehen, für die eine elterliche Bürgschaft besteht, sowie Angaben zu etwaigen Verhandlungen mit den deutschen Steuerbehörden darüber, ob das Unternehmen unterkapitalisiert ist. | I37: offen | K37: offen
B38: =6+(ROW(B38)-12)/100 -> 6.26 | D38: Bitte geben Sie eine kurze Beschreibung der Funktionen, die von den wichtigsten Unternehmen ausgeübt werden (z. B. F&E, Beschaffung, Produktion, Finanzierung, Verkauf, Management). | I38: offen | K38: offen
B39: =6+(ROW(B39)-12)/100 -> 6.27 | D39: Kopien der Verrechnungspreispolitik der Zielgruppe und der gruppeninternen Vereinbarungen. | I39: offen | K39: offen
D40: Wage Tax
B41: =6+(ROW(B41)-15)/100 -> 6.26 | D41: Angaben darüber, wer bei der Zielgesellschaft für Lohnsteuerangelegenheiten zuständig ist, Inanspruchnahme von Beratern usw. | I41: offen | K41: offen
B42: =6+(ROW(B42)-15)/100 -> 6.27 | D42: Kopie des letzten Lohnsteuerprüfungsberichts. | I42: offen | K42: offen
...

Sheet Legal
D1: =+Header!A3 -> Checkliste | H1: Update | I1: =+Header!A17 -> 44552
B2: Projekt | D2: =+Header!B4 -> PEGASUS
B3: Sektion | D3: Legal (Recht)
B5: Linie | C5: Priorität | D5: Datengrundlagen | E5: Gruppen | F5: Einheits | G5: Verantwortlich | H5: Kommentar | I5: Status | K5: Einheit 1 | L5: Einheit 2
E6: Ebene | F6: Ebene
D8: Gesellschaftsrecht
B9: =8+(ROW(B9)-8)/100 -> 8.01 | D9: Gründungsurkunde, Gesellschaftsvertrag, Handelsregisteranmeldung und Einzahlungsbelege der Einlage | I9: offen | K9: offen | L9: offen
B10: =8+(ROW(B10)-8)/100 -> 8.02 | D10: Gesellschafterliste (inkl. Anteilsbesitze, Kapitalanteile und deren Teilbarkeit) | I10: offen | K10: offen | L10: offen
B11: =8+(ROW(B11)-8)/100 -> 8.03 | D11: Gesellschaftervereinbarung, Satzungen (inkl. "change of control"-Bestimmungen) | I11: offen | K11: offen | L11: offen
B12: =8+(ROW(B12)-8)/100 -> 8.04 | D12: Gesellschafterbeschöüsse und Gesellschafterprotokolle | I12: offen | K12: offen | L12: offen
B13: =8+(ROW(B13)-8)/100 -> 8.05 | D13: Besondere Bestimmungen aus dem Gesellschaftsrecht (z.B. Squeeze Out) | I13: offen | K13: offen | L13: offen
D14: Vertragsrecht
B15: =8+(ROW(B15)-8-1)/100 -> 8.06 | D15: Kundenverträgen (laufende und zukünftige Beauftragungen, Rahmenverträge, wesentliche Altverträge) | I15: offen | K15: offen | L15: offen
B16: =8+(ROW(B16)-8-1)/100 -> 8.07 | D16: Lieferantenverträge | I16: offen | K16: offen | L16: offen
B17: =8+(ROW(B17)-8-1)/100 -> 8.08 | D17: Darlehensverträge (Covenant, Sicherheiten, „change of control“-Bestimmungen) | I17: offen | K17: offen | L17: offen
B18: =8+(ROW(B18)-8-1)/100 -> 8.09 | D18: Gewährleistungsverpflichtungen | I18: offen | K18: offen | L18: offen
B19: =8+(ROW(B19)-8-1)/100 -> 8.1 | D19: Geheimhaltungsverpflichtungen und Zusicherung von Schutzrechten (Kundenschutz, Mitarbeiterschutz, Knowhow, etc.) | I19: offen | K19: offen | L19: offen
B20: =8+(ROW(B20)-8-1)/100 -> 8.11 | D20: Allgemeine Geschäftsbedingungen (AGBs) und ggf. Abweichung von eigenen AGBs | I20: offen | K20: offen | L20: offen
D21: Arbeits- und Tarifrecht
B22: =8+(ROW(B22)-8-2)/100 -> 8.12 | D22: Individualverträge | K22: offen | L22: offen
B23: =8+(ROW(B23)-8-2)/100 -> 8.13 | D23: Betriebsvereinbarungen und tarifrechtlichen Bestimmungen | K23: offen | L23: offen
B24: =8+(ROW(B24)-8-2)/100 -> 8.14 | D24: Prüfung der Notwendigkeit des Betriebsübergang nach 613a BGB und die Auswirkungen, die dieser mit sich bringt (insbesondere Sozialpläne, Restrukturierungen, Abfindungszahlungen) | K24: offen | L24: offen

Sheet ESG
D1: =+Header!A3 -> Checkliste | H1: Update | I1: =+Header!A17 -> 44552
B2: Projekt | D2: =+Header!B4 -> PEGASUS
B3: Sektion | D3: ESG (Umwelt, Soziales und Governance)
B5: Linie | C5: Priorität | D5: Datengrundlagen | E5: Gruppen | F5: Einheits | G5: Verantwortlich | H5: Kommentar | I5: Status | K5: Einheit 1 | L5: Einheit 2
E6: Ebene | F6: Ebene
D8: Enviromental
B9: =7+(ROW(B9)-8)/100 -> 7.01 | D9: Einhaltung von regulatorischen Vorschriften | I9: offen | K9: offen | L9: offen
B10: =7+(ROW(B10)-8)/100 -> 7.02 | D10: Überwachung ökologischer Auswirkungen in der Produktion | I10: offen | K10: offen | L10: offen
B11: =7+(ROW(B11)-8)/100 -> 7.03 | D11: Emissionsminimierung | I11: offen | K11: offen | L11: offen
B12: =7+(ROW(B12)-8)/100 -> 7.04 | D12: Minimierung des Energie- und Wasserverbrauchs | I12: offen | K12: offen | L12: offen
B13: =7+(ROW(B13)-8)/100 -> 7.05 | D13: Restriktion jeglichen Schadstoffen in der Supply Chain | I13: offen | K13: offen | L13: offen
B14: =7+(ROW(B14)-8)/100 -> 7.06 | D14: Aufstellung eines Abfallmanagementsystems | I14: offen | K14: offen | L14: offen
B15: =7+(ROW(B15)-8)/100 -> 7.07 | D15: Schonung des Boden- und Grundwassers | I15: offen | K15: offen | L15: offen
B16: =7+(ROW(B16)-8)/100 -> 7.08 | D16: Einführung nachhaltiger Verpackungsdesigns | I16: offen | K16: offen | L16: offen
D17: Social
B18: =7+(ROW(B18)-8-1)/100 -> 7.09 | D18: Arbeitsschutz und Arbeitsbedingungen | I18: offen | K18: offen | L18: offen
B19: =7+(ROW(B19)-8-1)/100 -> 7.1 | D19: Bewertung sozialer Auswirkung des Produktportfolios | I19: offen | K19: offen | L19: offen
B20: =7+(ROW(B20)-8-1)/100 -> 7.11 | D20: Kundendatenschutz / Produktregulierungen | I20: offen | K20: offen | L20: offen
B21: =7+(ROW(B21)-8-1)/100 -> 7.12 | D21: Faire Offenlegung und Kennzeichnung / Faires Marketing | I21: offen | K21: offen | L21: offen
B22: =7+(ROW(B22)-8-1)/100 -> 7.13 | D22: Sicherstellung der Diversität und Chancengleichheit im Unternehmen | I22: offen | K22: offen | L22: offen
D23: Governance
B24: =7+(ROW(B24)-8-2)/100 -> 7.14 | D24: Mechanismen zur Vorbeugung von Korruption | I24: offen | K24: offen | L24: offen
B25: =7+(ROW(B25)-8-2)/100 -> 7.15 | D25: Etablierung eines Risikomanagmentsystems | I25: offen | K25: offen | L25: offen
B26: =7+(ROW(B26)-8-2)/100 -> 7.16 | D26: Wettbewerbsrechtliches Verhalten | I26: offen | K26: offen | L26: offen
B27: =7+(ROW(B27)-8-2)/100 -> 7.17 | D27: Einhaltung und Überwachung der Richtlinien innerhalb der Supply Chain | I27: offen | K27: offen | L27: offen

Sheet Tech_IT
D1: =+Header!A3 -> Checkliste | E1: Update | F1: =+Header!A17 -> 44552
B2: Projekt | D2: =+Header!B4 -> PEGASUS
B3: Sektion | D3: Tech und IT
B5: Linie | C5: Priorität | D5: Datengrundlagen | E5: Gruppen | F5: Einheits | G5: Verantwortlich | H5: Kommentar | I5: Status | K5: Einheit 1 | L5: Einheit 2
E6: Ebene | F6: Ebene
D8: Berichte / Daten / Informationen über:
B9: =9+(ROW(B9)-8)/100 -> 9.01 | D9: Software- und Hardware-Architektur der eingesetzten Systeme | I9: offen | K9: offen | L9: offen
B10: =9+(ROW(B10)-8)/100 -> 9.02 | D10: IT-Security: Datensicherheit und -schutz, zum Beispiel Backup-Routinen und Zugriffsschutz von Außen und Innen | I10: offen | K10: offen | L10: offen
B11: =9+(ROW(B11)-8)/100 -> 9.03 | D11: IT-Team und Verantwortlichkeit | I11: offen | K11: offen | L11: offen
B12: =9+(ROW(B12)-8)/100 -> 9.04 | D12: Prüfungsberichte externer Prüfer, zum Beispiel im Rahmen von Software-Zertifizierungen oder Prüfung von Kontrollsystemen, Untersuchungsberichte von Hacker-Angriffen,ect. | I12: offen | K12: offen | L12: offen
B13: =9+(ROW(B13)-8)/100 -> 9.05 | D13: Untersuchung externer Software oder auch eingesetzter Open-Source-Software | I13: offen | K13: offen | L13: offen
B14: =9+(ROW(B14)-8)/100 -> 9.06 | D14: Skalierbarkeit | I14: offen | K14: offen | L14: offen
B15: =9+(ROW(B15)-8)/100 -> 9.07 | D15: Codereview | I15: offen | K15: offen | L15: offen
